Workbook

Sheet Assumptions
A1: ASSUMPTION | B1: VALUE
A3: REVENUE GROWTH RATES
A4: Productivity & Business (2024E) | B4: 0.08
A5: Productivity & Business (2025E) | B5: 0.07
A6: Productivity & Business (2026E) | B6: 0.065
A7: Productivity & Business (2027E) | B7: 0.06
A8: Productivity & Business (2028E) | B8: 0.055
A9: Intelligent Cloud (2024E) | B9: 0.28
A10: Intelligent Cloud (2025E) | B10: 0.22
A11: Intelligent Cloud (2026E) | B11: 0.18
A12: Intelligent Cloud (2027E) | B12: 0.15
A13: Intelligent Cloud (2028E) | B13: 0.12
A14: More Personal Computing (2024E) | B14: 0.08
A15: More Personal Computing (2025E) | B15: 0.06
... A18: More Personal Computing (2028E) | B18: 0.03
A20: MARGIN ASSUMPTIONS
A21: Gross Margin % | B21: 0.689
A22: R&D as % of Revenue | B22: 0.137
A23: Sales & Marketing as % of Revenue | B23: 0.104
A24: G&A as % of Revenue | B24: 0.069
A26: TAX & CAPITAL ALLOCATION
A27: Effective Tax Rate | B27: 0.18
A28: CapEx as % of Revenue | B28: 0.084
A30: WORKING CAPITAL ASSUMPTIONS
A31: Days Sales Outstanding (DSO) | B31: 41
A32: Days Inventory Outstanding (DIO) | B32: 0
A33: Days Payable Outstanding (DPO) | B33: 74
A35: WACC INPUTS
A36: Risk-Free Rate | B36: 0.042
A37: Equity Risk Premium | B37: 0.055
A38: Beta | B38: 0.95
A39: Cost of Debt (Pre-tax) | B39: 0.035
A40: Tax Rate for WACC | B40: 0.18
A41: Debt/Equity Ratio | B41: 0.25
A43: CALCULATED WACC
A44: Cost of Equity (CAPM) | B44: =B36+(B37*B38)
A45: Cost of Debt (After-tax) | B45: =B39*(1-B40)
A46: Weight of Equity | B46: =1/(1+B41)
A47: Weight of Debt | B47: =B41/(1+B41)
A48: WACC | B48: =(B44*B46)+(B45*B47)
...

Sheet Income Statement
B1: 2021 | C1: 2022 | D1: 2023 | E1: 2024 | F1: 2025 | G1: 2026 | H1: 2027 | I1: 2028
A3: REVENUE
A4: Productivity & Business | B4: 53.9 | C4: 63.4 | D4: 69.3 | E4: =D4*(1+0.08) | F4: =E4*(1+0.07) | G4: =F4*(1+0.065) | H4: =G4*(1+0.06) | I4: =H4*(1+0.055)
A5: Intelligent Cloud | B5: 60.1 | C5: 75.3 | D5: 87.9 | E5: =D5*(1+0.28) | F5: =E5*(1+0.22) | G5: =F5*(1+0.18) | H5: =G5*(1+0.15) | I5: =H5*(1+0.12)
A6: More Personal Computing | B6: 54.1 | C6: 59.7 | D6: 54.7 | E6: =D6*(1+0.08) | F6: =E6*(1+0.06) | G6: =F6*(1+0.05) | H6: =G6*(1+0.04) | I6: =H6*(1+0.03)
A8: Total Revenue | B8: =B4+B5+B6 | C8: =C4+C5+C6 | D8: =D4+D5+D6 | E8: =E4+E5+E6 | F8: =F4+F5+F6 | G8: =G4+G5+G6 | H8: =H4+H5+H6 | I8: =I4+I5+I6
A10: Cost of Revenue | B10: =B8*(1-Assumptions!$B$21) | C10: =C8*(1-Assumptions!$B$21) | D10: =D8*(1-Assumptions!$B$21) | E10: =E8*(1-Assumptions!$B$21) | F10: =F8*(1-Assumptions!$B$21) | G10: =G8*(1-Assumptions!$B$21) | H10: =H8*(1-Assumptions!$B$21) | I10: =I8*(1-Assumptions!$B$21)
A11: Gross Profit | B11: =B8-B10 | C11: =C8-C10 | D11: =D8-D10 | E11: =E8-E10 | F11: =F8-F10 | G11: =G8-G10 | H11: =H8-H10 | I11: =I8-I10
A13: R&D | B13: =B8*Assumptions!$B$22 | C13: =C8*Assumptions!$B$22 | D13: =D8*Assumptions!$B$22 | E13: =E8*Assumptions!$B$22 | F13: =F8*Assumptions!$B$22 | G13: =G8*Assumptions!$B$22 | H13: =H8*Assumptions!$B$22 | I13: =I8*Assumptions!$B$22
A14: Sales & Marketing | B14: =B8*Assumptions!$B$23 | C14: =C8*Assumptions!$B$23 | D14: =D8*Assumptions!$B$23 | E14: =E8*Assumptions!$B$23 | F14: =F8*Assumptions!$B$23 | G14: =G8*Assumptions!$B$23 | H14: =H8*Assumptions!$B$23 | I14: =I8*Assumptions!$B$23
A15: General & Administrative | B15: =B8*Assumptions!$B$24 | C15: =C8*Assumptions!$B$24 | D15: =D8*Assumptions!$B$24 | E15: =E8*Assumptions!$B$24 | F15: =F8*Assumptions!$B$24 | G15: =G8*Assumptions!$B$24 | H15: =H8*Assumptions!$B$24 | I15: =I8*Assumptions!$B$24
A16: Operating Income (EBIT) | B16: =B11-B13-B14-B15 | C16: =C11-C13-C14-C15 | D16: =D11-D13-D14-D15 | E16: =E11-E13-E14-E15 | F16: =F11-F13-F14-F15 | G16: =G11-G13-G14-G15 | H16: =H11-H13-H14-H15 | I16: =I11-I13-I14-I15
A18: Interest Income | B18: 1800 | C18: 2687 | D18: 3307 | E18: =D18*1.05 | F18: =E18*1.05 | G18: =F18*1.05 | H18: =G18*1.05 | I18: =H18*1.05
A19: Interest Expense | B19: 186 | C19: 263 | D19: 365 | E19: =D19*1.08 | F19: =E19*1.08 | G19: =F19*1.08 | H19: =G19*1.08 | I19: =H19*1.08
A21: Pre-Tax Income | B21: =B16+B18-B19 | C21: =C16+C18-C19 | D21: =D16+D18-D19 | E21: =E16+E18-E19 | F21: =F16+F18-F19 | G21: =G16+G18-G19 | H21: =H16+H18-H19 | I21: =I16+I18-I19
A22: Income Tax | B22: =B21*0.135 | C22: =C21*0.128 | D22: =D21*0.136 | E22: =E21*Assumptions!$B$27 | F22: =F21*Assumptions!$B$27 | G22: =G21*Assumptions!$B$27 | H22: =H21*Assumptions!$B$27 | I22: =I21*Assumptions!$B$27
A23: Net Income | B23: =B21-B22 | C23: =C21-C22 | D23: =D21-D22 | E23: =E21-E22 | F23: =F21-F22 | G23: =G21-G22 | H23: =H21-H22 | I23: =I21-I22

Sheet Balance Sheet
B1: 2021 | C1: 2022 | D1: 2023 | E1: 2024 | F1: 2025 | G1: 2026 | H1: 2027 | I1: 2028
A3: ASSETS
A4: Current Assets
A5: Cash and Equivalents | B5: 11321 | C5: 10496 | D5: 9790 | E5: 10500 | F5: 11200 | G5: 12100 | H5: 13200 | I5: 14400
A6: Short-term Investments | B6: 10949 | C6: 12768 | D6: 14254 | E6: 15300 | F6: 16400 | G6: 17500 | H6: 18700 | I6: 20000
A7: Accounts Receivable | B7: 39000 | C7: 44100 | D7: 47482 | E7: 51000 | F7: 54000 | G7: 57500 | H7: 61000 | I7: 65000
A8: Inventory | B8: 0 | C8: 0 | D8: 0 | E8: 0 | F8: 0 | G8: 0 | H8: 0 | I8: 0
A9: Total Current Assets | B9: =B5+B6+B7+B8 | C9: =C5+C6+C7+C8 | D9: =D5+D6+D7+D8 | E9: =E5+E6+E7+E8 | F9: =F5+F6+F7+F8 | G9: =G5+G6+G7+G8 | H9: =H5+H6+H7+H8 | I9: =I5+I6+I7+I8
A11: Non-Current Assets
A12: Property, Plant & Equipment, net | B12: 47365 | C12: 52857 | D12: 59569 | E12: 64000 | F12: 68500 | G12: 73200 | H12: 78200 | I12: 83700
A13: Goodwill | B13: 42262 | C13: 42262 | D13: 42262 | E13: 42262 | F13: 42262 | G13: 42262 | H13: 42262 | I13: 42262
A14: Intangible Assets | B14: 21606 | C14: 21606 | D14: 21606 | E14: 21606 | F14: 21606 | G14: 21606 | H14: 21606 | I14: 21606
A15: Other Long-term Assets | B15: 9251 | C15: 9251 | D15: 9251 | E15: 9251 | F15: 9251 | G15: 9251 | H15: 9251 | I15: 9251
A16: Total Assets | B16: =B9+B12+B13+B14+B15 | C16: =C9+C12+C13+C14+C15 | D16: =D9+D12+D13+D14+D15 | E16: =E9+E12+E13+E14+E15 | F16: =F9+F12+F13+F14+F15 | G16: =G9+G12+G13+G14+G15 | H16: =H9+H12+H13+H14+H15 | I16: =I9+I12+I13+I14+I15
A19: LIABILITIES & SHAREHOLDERS' EQUITY
A20: Current Liabilities
A21: Accounts Payable | B21: 9302 | C21: 10853 | D21: 12029 | E21: 13000 | F21: 14000 | G21: 15100 | H21: 16300 | I21: 17600
A22: Accrued Expenses | B22: 13529 | C22: 14850 | D22: 16500 | E22: 17500 | F22: 18700 | G22: 20000 | H22: 21400 | I22: 23000
A23: Current Portion of Debt | B23: 3101 | C23: 2775 | D23: 2869 | E23: 3000 | F23: 3200 | G23: 3400 | H23: 3600 | I23: 3800
A24: Deferred Revenue | B24: 36636 | C24: 44674 | D24: 52857 | E24: 56800 | F24: 60500 | G24: 64500 | H24: 68700 | I24: 73300
A25: Total Current Liabilities | B25: =B21+B22+B23+B24 | C25: =C21+C22+C23+C24 | D25: =D21+D22+D23+D24 | E25: =E21+E22+E23+E24 | F25: =F21+F22+F23+F24 | G25: =G21+G22+G23+G24 | H25: =H21+H22+H23+H24 | I25: =I21+I22+I23+I24
A26: Long-term Debt | B26: 47687 | C26: 47139 | D26: 47229 | E26: 47000 | F26: 47000 | G26: 47000 | H26: 47000 | I26: 47000
A27: Deferred Tax Liability | B27: 2082 | C27: 2082 | D27: 2082 | E27: 2082 | F27: 2082 | G27: 2082 | H27: 2082 | I27: 2082
A28: Total Liabilities | B28: =B25+B26+B27 | C28: =C25+C26+C27 | D28: =D25+D26+D27 | E28: =E25+E26+E27 | F28: =F25+F26+F27 | G28: =G25+G26+G27 | H28: =H25+H26+H27 | I28: =I25+I26+I27
A30: Shareholders' Equity
A31: Common Stock & Paid-in Capital | B31: 78156 | C31: 81044 | D31: 82951 | E31: 85000 | F31: 88000 | G31: 91000 | H31: 94000 | I31: 97500
A32: Retained Earnings | B32: 109717 | C32: 123498 | D32: 139364 | E32: 158000 | F32: 179000 | G32: 203000 | H32: 230000 | I32: 261000
A33: Accumulated Other Comprehensive Income | B33: -7644 | C33: -8345 | D33: -9652 | E33: -10000 | F33: -11000 | G33: -12000 | H33: -13000 | I33: -14000
A34: Total Shareholders' Equity | B34: =B31+B32+B33 | C34: =C31+C32+C33 | D34: =D31+D32+D33 | E34: =E31+E32+E33 | F34: =F31+F32+F33 | G34: =G31+G32+G33 | H34: =H31+H32+H33 | I34: =I31+I32+I33
A35: Total Liabilities & Equity | B35: =B28+B34 | C35: =C28+C34 | D35: =D28+D34 | E35: =E28+E34 | F35: =F28+F34 | G35: =G28+G34 | H35: =H28+H34 | I35: =I28+I34
A37: BALANCE CHECK (Assets - L - E) | B37: =B16-B35 | C37: =C16-C35 | D37: =D16-D35 | E37: =E16-E35 | F37: =F16-F35 | G37: =G16-G35 | H37: =H16-H35 | I37: =I16-I35

Sheet Cash Flow Statement
B1: 2021 | C1: 2022 | D1: 2023 | E1: 2024 | F1: 2025 | G1: 2026 | H1: 2027 | I1: 2028
A3: OPERATING ACTIVITIES
A4: Net Income | B4: ='Income Statement'!B51 | C4: ='Income Statement'!C51 | D4: ='Income Statement'!D51 | E4: ='Income Statement'!E51 | F4: ='Income Statement'!F51 | G4: ='Income Statement'!G51 | H4: ='Income Statement'!H51 | I4: ='Income Statement'!I51
A5: Depreciation & Amortization | B5: 10164 | C5: 11473 | D5: 12992 | E5: 13900 | F5: 14800 | G5: 15800 | H5: 16900 | I5: 18100
A6: Stock-Based Compensation | B6: 8474 | C6: 8886 | D6: 9345 | E6: 10000 | F6: 10700 | G6: 11450 | H6: 12250 | I6: 13100
A7: Working Capital Changes | B7: -1223 | C7: 1800 | D7: 2100 | E7: 1200 | F7: 800 | G7: 500 | H7: 300 | I7: 200
A8: Other Operating | B8: 445 | C8: -1348 | D8: 1239 | E8: 500 | F8: 300 | G8: 200 | H8: 100 | I8: 50
A9: Operating Cash Flow | B9: =B4+B5+B6+B7+B8 | C9: =C4+C5+C6+C7+C8 | D9: =D4+D5+D6+D7+D8 | E9: =E4+E5+E6+E7+E8 | F9: =F4+F5+F6+F7+F8 | G9: =G4+G5+G6+G7+G8 | H9: =H4+H5+H6+H7+H8 | I9: =I4+I5+I6+I7+I8
B10: ='Income Statement'!B51 | C10: ='Income Statement'!C51 | D10: ='Income Statement'!D51 | E10: ='Income Statement'!E51 | F10: ='Income Statement'!F51 | G10: ='Income Statement'!G51 | H10: ='Income Statement'!H51 | I10: ='Income Statement'!I51
A11: INVESTING ACTIVITIES
A12: Capital Expenditures | B12: =-'Income Statement'!B2*Assumptions!$B$47 | C12: =-'Income Statement'!C2*Assumptions!$B$47 | D12: =-'Income Statement'!D2*Assumptions!$B$47 | E12: =-'Income Statement'!E2*Assumptions!$B$47 | F12: =-'Income Statement'!F2*Assumptions!$B$47 | G12: =-'Income Statement'!G2*Assumptions!$B$47 | H12: =-'Income Statement'!H2*Assumptions!$B$47 | I12: =-'Income Statement'!I2*Assumptions!$B$47
A13: Acquisitions | B13: 0 | C13: 0 | D13: 0 | E13: -2000 | F13: 0 | G13: 0 | H13: 0 | I13: 0
A14: Investment Sales/(Purchases) | B14: 6500 | C14: -1900 | D14: -1600 | E14: -1000 | F14: -1100 | G14: -1200 | H14: -1300 | I14: -1400
A15: Investing Cash Flow | B15: =B12+B13+B14 | C15: =C12+C13+C14 | D15: =D12+D13+D14 | E15: =E12+E13+E14 | F15: =F12+F13+F14 | G15: =G12+G13+G14 | H15: =H12+H13+H14 | I15: =I12+I13+I14
A17: FINANCING ACTIVITIES
A18: Debt Issuance/(Repayment) | B18: 6000 | C18: -4000 | D18: 0 | E18: 0 | F18: 0 | G18: 0 | H18: 0 | I18: 0
A19: Share Repurchases | B19: -22110 | C19: -26608 | D19: -27185 | E19: -30000 | F19: -32000 | G19: -34000 | H19: -36000 | I19: -38000
A20: Dividends Paid | B20: -15158 | C20: -15952 | D20: -18466 | E20: -20000 | F20: -21000 | G20: -22500 | H20: -24000 | I20: -25500
A21: Financing Cash Flow | B21: =B18+B19+B20 | C21: =C18+C19+C20 | D21: =D18+D19+D20 | E21: =E18+E19+E20 | F21: =F18+F19+F20 | G21: =G18+G19+G20 | H21: =H18+H19+H20 | I21: =I18+I19+I20
A23: Net Change in Cash | B23: =B9+B15+B21 | C23: =C9+C15+C21 | D23: =D9+D15+D21 | E23: =E9+E15+E21 | F23: =F9+F15+F21 | G23: =G9+G15+G21 | H23: =H9+H15+H21 | I23: =I9+I15+I21
A24: Beginning Cash | B24: ='Balance Sheet'!A3 | C24: ='Balance Sheet'!B3 | D24: ='Balance Sheet'!C3 | E24: ='Balance Sheet'!D3 | F24: ='Balance Sheet'!E3 | G24: ='Balance Sheet'!F3 | H24: ='Balance Sheet'!G3 | I24: =H24
A25: Ending Cash | B25: =B24+B23 | C25: =C24+C23 | D25: =D24+D23 | E25: =E24+E23 | F25: =F24+F23 | G25: =G24+G23 | H25: =H24+H23 | I25: =I24+I23

Sheet DCF Valuation
A1: DCF VALUATION MODEL
A3: UNLEVERED FREE CASH FLOW PROJECTIONS ($ millions)
A4: Year | B4: 2024E | C4: 2025E | D4: 2026E | E4: 2027E | F4: 2028E
A5: EBIT | B5: ='Income Statement'!B30 | C5: ='Income Statement'!C30 | D5: ='Income Statement'!D30 | E5: ='Income Statement'!E30 | F5: ='Income Statement'!F30
A6: Less: Tax on EBIT | B6: =B5*Assumptions!$B$28 | C6: =C5*Assumptions!$B$28 | D6: =D5*Assumptions!$B$28 | E6: =E5*Assumptions!$B$28 | F6: =F5*Assumptions!$B$28
A7: NOPAT (EBIT * (1-Tax)) | B7: =B5-B6 | C7: =C5-C6 | D7: =D5-D6 | E7: =E5-E6 | F7: =F5-F6
A8: Add: Depreciation & Amortization | B8: ='Cash Flow Statement'!B17 | C8: ='Cash Flow Statement'!C17 | D8: ='Cash Flow Statement'!D17 | E8: ='Cash Flow Statement'!E17 | F8: ='Cash Flow Statement'!F17
A9: Less: CapEx | B9: ='Cash Flow Statement'!B22 | C9: ='Cash Flow Statement'!C22 | D9: ='Cash Flow Statement'!D22 | E9: ='Cash Flow Statement'!E22 | F9: ='Cash Flow Statement'!F22
A10: Less: Change in NWC | B10: ='Cash Flow Statement'!B20 | C10: ='Cash Flow Statement'!C20 | D10: ='Cash Flow Statement'!D20 | E10: ='Cash Flow Statement'!E20 | F10: ='Cash Flow Statement'!F20
A11: Unlevered Free Cash Flow | B11: =B7+B8+B9+B10 | C11: =C7+C8+C9+C10 | D11: =D7+D8+D9+D10 | E11: =E7+E8+E9+E10 | F11: =F7+F8+F9+F10
A13: Discount Factors (1/(1+WACC)^n) | B13: =1/(1+Assumptions!$B$67)^1 | C13: =1/(1+Assumptions!$B$67)^2 | D13: =1/(1+Assumptions!$B$67)^3 | E13: =1/(1+Assumptions!$B$67)^4 | F13: =1/(1+Assumptions!$B$67)^5
A14: PV of UFCF | B14: =B11*B13 | C14: =C11*C13 | D14: =D11*D13 | E14: =E11*E13 | F14: =F11*F13
A15: Sum PV of Explicit FCF (2024-2028) | B15: ='Income Statement'!B30 | C15: ='Income Statement'!C30 | D15: ='Income Statement'!D30 | E15: ='Income Statement'!E30 | F15: ='Income Statement'!F30 | G15: ='Income Statement'!G30 | H15: ='Income Statement'!H30 | I15: ='Income Statement'!I30
A17: TERMINAL VALUE
A18: 2028E UFCF | B18: =F11
A19: Terminal Growth Rate | B19: =Assumptions!$B$72
A20: Terminal Year UFCF | B20: =B18*(1+B19)
A21: WACC | B21: =Assumptions!$B$67
A22: Terminal Value = TV UFCF / (WACC - g) | B22: =B20/(B21-B19)
A23: Discount Factor (Year 5) | B23: =1/(1+B21)^5
A24: PV of Terminal Value | B24: =B22*B23
A26: VALUATION SUMMARY
A27: PV of Explicit FCF | B27: =B15
A28: PV of Terminal Value | B28: =B24
A29: Enterprise Value | B29: =B27+B28
A30: Less: Net Debt | B30: =('Balance Sheet'!B10+'Balance Sheet'!B27)-('Balance Sheet'!B3)
A31: Equity Value | B31: =B29-B30
A32: Shares Outstanding (millions) | B32: 7725
A33: IMPLIED SHARE PRICE | B33: =B31/B32
A36: SENSITIVITY TABLE: SHARE PRICE
A37: WACC \ Terminal Growth | B37: 2.0% | C37: 2.5% | D37: 3.0% | E37: 3.5% | F37: 4.0%
A38: 7.0% | B38: =(B15+(23*(B20*0.020)/(0.0700-0.0200)))-B30)/B32 | C38: =(B15+(23*(B20*0.025)/(0.0700-0.0250)))-B30)/B32 | D38: =(B15+(23*(B20*0.030)/(0.0700-0.0300)))-B30)/B32 | E38: =(B15+(23*(B20*0.035)/(0.0700-0.0350)))-B30)/B32 | F38: =(B15+(23*(B20*0.040)/(0.0700-0.0400)))-B30)/B32
A39: 7.5% | B39: =(B15+(23*(B20*0.020)/(0.0750-0.0200)))-B30)/B32 | C39: =(B15+(23*(B20*0.025)/(0.0750-0.0250)))-B30)/B32 | D39: =(B15+(23*(B20*0.030)/(0.0750-0.0300)))-B30)/B32 | E39: =(B15+(23*(B20*0.035)/(0.0750-0.0350)))-B30)/B32 | F39: =(B15+(23*(B20*0.040)/(0.0750-0.0400)))-B30)/B32
A40: 8.0% | B40: =(B15+(23*(B20*0.020)/(0.0800-0.0200)))-B30)/B32 | C40: =(B15+(23*(B20*0.025)/(0.0800-0.0250)))-B30)/B32 | D40: =(B15+(23*(B20*0.030)/(0.0800-0.0300)))-B30)/B32 | E40: =(B15+(23*(B20*0.035)/(0.0800-0.0350)))-B30)/B32 | F40: =(B15+(23*(B20*0.040)/(0.0800-0.0400)))-B30)/B32
A41: 8.5% | B41: =(B15+(23*(B20*0.020)/(0.0850-0.0200)))-B30)/B32 | C41: =(B15+(23*(B20*0.025)/(0.0850-0.0250)))-B30)/B32 | D41: =(B15+(23*(B20*0.030)/(0.0850-0.0300)))-B30)/B32 | E41: =(B15+(23*(B20*0.035)/(0.0850-0.0350)))-B30)/B32 | F41: =(B15+(23*(B20*0.040)/(0.0850-0.0400)))-B30)/B32
A42: 9.0% | B42: =(B15+(23*(B20*0.020)/(0.0900-0.0200)))-B30)/B32 | C42: =(B15+(23*(B20*0.025)/(0.0900-0.0250)))-B30)/B32 | D42: =(B15+(23*(B20*0.030)/(0.0900-0.0300)))-B30)/B32 | E42: =(B15+(23*(B20*0.035)/(0.0900-0.0350)))-B30)/B32 | F42: =(B15+(23*(B20*0.040)/(0.0900-0.0400)))-B30)/B32
A43: 9.5% | B43: =(B15+(23*(B20*0.020)/(0.0950-0.0200)))-B30)/B32 | C43: =(B15+(23*(B20*0.025)/(0.0950-0.0250)))-B30)/B32 | D43: =(B15+(23*(B20*0.030)/(0.0950-0.0300)))-B30)/B32 | E43: =(B15+(23*(B20*0.035)/(0.0950-0.0350)))-B30)/B32 | F43: =(B15+(23*(B20*0.040)/(0.0950-0.0400)))-B30)/B32
A44: 10.0% | B44: =(B15+(23*(B20*0.020)/(0.1000-0.0200)))-B30)/B32 | C44: =(B15+(23*(B20*0.025)/(0.1000-0.0250)))-B30)/B32 | D44: =(B15+(23*(B20*0.030)/(0.1000-0.0300)))-B30)/B32 | E44: =(B15+(23*(B20*0.035)/(0.1000-0.0350)))-B30)/B32 | F44: =(B15+(23*(B20*0.040)/(0.1000-0.0400)))-B30)/B32
A45: 10.5% | B45: =(B15+(23*(B20*0.020)/(0.1050-0.0200)))-B30)/B32 | C45: =(B15+(23*(B20*0.025)/(0.1050-0.0250)))-B30)/B32 | D45: =(B15+(23*(B20*0.030)/(0.1050-0.0300)))-B30)/B32 | E45: =(B15+(23*(B20*0.035)/(0.1050-0.0350)))-B30)/B32 | F45: =(B15+(23*(B20*0.040)/(0.1050-0.0400)))-B30)/B32
A46: 11.0% | B46: =(B15+(23*(B20*0.020)/(0.1100-0.0200)))-B30)/B32 | C46: =(B15+(23*(B20*0.025)/(0.1100-0.0250)))-B30)/B32 | D46: =(B15+(23*(B20*0.030)/(0.1100-0.0300)))-B30)/B32 | E46: =(B15+(23*(B20*0.035)/(0.1100-0.0350)))-B30)/B32 | F46: =(B15+(23*(B20*0.040)/(0.1100-0.0400)))-B30)/B32
...

Sheet Comparable Companies
A1: COMPARABLE COMPANY ANALYSIS
A3: Company | B3: Market Cap ($B) | C3: EV ($B) | D3: Revenue ($B) | E3: EBITDA ($B) | F3: EV/Revenue | G3: EV/EBITDA | H3: P/E
A4: Apple | B4: 3000 | C4: 2850 | D4: 394 | E4: 124 | F4: =C4/D4 | G4: =C4/E4 | H4: =B4/D4*0.30
A5: Google (Alphabet) | B5: 1800 | C5: 1750 | D5: 307 | E5: 100 | F5: =C5/D5 | G5: =C5/E5 | H5: =B5/D5*0.30
A6: Amazon | B6: 1950 | C6: 1800 | D6: 575 | E6: 95 | F6: =C6/D6 | G6: =C6/E6 | H6: =B6/D6*0.30
A7: Meta | B7: 1200 | C7: 1150 | D7: 135 | E7: 50 | F7: =C7/D7 | G7: =C7/E7 | H7: =B7/D7*0.30
A8: Salesforce | B8: 280 | C8: 260 | D8: 34 | E8: 12 | F8: =C8/D8 | G8: =C8/E8 | H8: =B8/D8*0.30
A9: Oracle | B9: 330 | C9: 310 | D9: 52 | E9: 19 | F9: =C9/D9 | G9: =C9/E9 | H9: =B9/D9*0.30
A10: SAP | B10: 160 | C10: 150 | D10: 32 | E10: 10 | F10: =C10/D10 | G10: =C10/E10 | H10: =B10/D10*0.30
A12: MEDIAN | F12: =MEDIAN(F4:F10) | G12: =MEDIAN(G4:G10) | H12: =MEDIAN(H4:H10)
A13: MEAN | F13: =AVERAGE(F4:F10) | G13: =AVERAGE(G4:G10) | H13: =AVERAGE(H4:H10)
A15: MICROSOFT VALUATION
A16: 2023E Revenue (actual) | B16: ='Income Statement'!D2
A17: 2023E EBITDA | B17: ='Income Statement'!D30*(1+0.15)
A18: Median EV/Revenue Multiple | B18: =F12
A19: Implied EV (EV/Revenue) | B19: =B16*B18
A20: Median EV/EBITDA Multiple | B20: =G12
A21: Implied EV (EV/EBITDA) | B21: =B17*B20
A22: Average Implied EV | B22: =(B19+B21)/2
A23: Less: Net Debt | B23: =('Balance Sheet'!C10+'Balance Sheet'!C27)-('Balance Sheet'!C3)
A24: Implied Equity Value | B24: =B22-B23
A25: Shares Outstanding | B25: 7725
A26: IMPLIED SHARE PRICE | B26: =B24/B25
B52: =('Balance Sheet'!C10+'Balance Sheet'!C27)-('Balance Sheet'!C3)

Sheet Transaction Multiples
A1: PRECEDENT TRANSACTION ANALYSIS
A3: Transaction | B3: Deal Value ($B) | C3: EV/Revenue | D3: EV/EBITDA | E3: Year
A4: Microsoft/Activision Blizzard | B4: 69 | C4: 10 | D4: 24 | E4: 2023
A5: Broadcom/VMware | B5: 61 | C5: 8.5 | D5: 25 | E5: 2023
A6: Adobe/Figma (Withdrawn) | B6: 20 | C6: 50 | D6: 35 | E6: 2022
A7: Salesforce/Slack | B7: 27.7 | C7: 26 | D7: 32 | E7: 2021
A8: Microsoft/Nuance | B8: 19.7 | C8: 14 | D8: 20 | E8: 2021
A10: MEDIAN | C10: =MEDIAN(C4:C8) | D10: =MEDIAN(D4:D8)
A11: MEAN | C11: =AVERAGE(C4:C8) | D11: =AVERAGE(D4:D8)
A13: MICROSOFT VALUATION USING TRANSACTION MULTIPLES
A14: 2023E Revenue | B14: ='Income Statement'!D2
A15: 2023E EBITDA (est.) | B15: ='Income Statement'!D30*1.15
A16: Median EV/Revenue | B16: =C10
A17: Implied EV (EV/Revenue) | B17: =B14*B16
A18: Median EV/EBITDA | B18: =D10
A19: Implied EV (EV/EBITDA) | B19: =B15*B18
A20: Average Implied EV | B20: =(B17+B19)/2
A21: Less: Net Debt | B21: =('Balance Sheet'!C10+'Balance Sheet'!C27)-('Balance Sheet'!C3)
A22: Implied Equity Value | B22: =B20-B21
A23: Shares Outstanding | B23: 7725
A24: IMPLIED SHARE PRICE | B24: =B22/B23
B28: =('Balance Sheet'!C10+'Balance Sheet'!C27)-('Balance Sheet'!C3)

Sheet Valuation Summary
A1: VALUATION SUMMARY
A3: Valuation Method | B3: Low | C3: Mid | D3: High
A4: DCF Valuation | B4: ='DCF Valuation'!B39 | C4: ='DCF Valuation'!B41 | D4: ='DCF Valuation'!B48
A5: Comparable Companies | B5: ='Comparable Companies'!B47*0.90 | C5: ='Comparable Companies'!B47 | D5: ='Comparable Companies'!B47*1.10
A6: Transaction Multiples | B6: ='Transaction Multiples'!B35*0.90 | C6: ='Transaction Multiples'!B35 | D6: ='Transaction Multiples'!B35*1.10
A8: Current Trading Price (Reference) | B8: 380
A10: VALUATION RANGE SUMMARY
A11: Minimum Value | B11: =MIN(B4:B6)
A12: Maximum Value | B12: =MAX(D4:D6)
A13: Average Value | B13: =AVERAGE(B4:D6)
A16: FOOTBALL FIELD CHART DATA
A17: Valuation Method | B17: Low | C17: High
A18: DCF | B18: =B4 | C18: =D4
A19: Comparable Companies | B19: =B5 | C19: =D5
A20: Transaction Multiples | B20: =B6 | C20: =D6
